<?xml version="1.0"?>
<robot name="mecanum4_lidar">

  <link name="base_link">
    <visual>
      <origin xyz="0 0 0.12" rpy="0 0 0"/>
      <geometry>
        <box size="0.40 0.30 0.12"/>
      </geometry>
    </visual>
    <collision>
      <origin xyz="0 0 0.12" rpy="0 0 0"/>
      <geometry>
        <box size="0.40 0.30 0.12"/>
      </geometry>
    </collision>
    <inertial>
      <origin xyz="0 0 0.12" rpy="0 0 0"/>
      <mass value="5.0"/>
      <inertia ixx="0.0475" ixy="0.0" ixz="0.0" iyy="0.0727" iyz="0.0" izz="0.1042"/>
    </inertial>
  </link>

  <link name="wheel_fl_link">
    <visual>
      <origin xyz="0 0 0" rpy="1.5707963 0 0"/>
      <geometry><cylinder radius="0.05" length="0.03"/></geometry>
    </visual>
    <collision>
      <origin xyz="0 0 0" rpy="1.5707963 0 0"/>
      <geometry><cylinder radius="0.05" length="0.03"/></geometry>
    </collision>
    <inertial>
      <origin xyz="0 0 0" rpy="0 0 0"/>
      <mass value="0.5"/>
      <inertia ixx="0.0004" ixy="0.0" ixz="0.0" iyy="0.0002" iyz="0.0" izz="0.0004"/>
    </inertial>
  </link>
  <joint name="wheel_fl_joint" type="continuous">
    <parent link="base_link"/>
    <child link="wheel_fl_link"/>
    <origin xyz="0.16 0.18 0.05" rpy="0 0 0"/>
    <axis xyz="0 1 0"/>
    <dynamics damping="0.01" friction="0.0"/>
  </joint>

  <link name="wheel_fr_link">
    <visual>
      <origin xyz="0 0 0" rpy="1.5707963 0 0"/>
      <geometry><cylinder radius="0.05" length="0.03"/></geometry>
    </visual>
    <collision>
      <origin xyz="0 0 0" rpy="1.5707963 0 0"/>
      <geometry><cylinder radius="0.05" length="0.03"/></geometry>
    </collision>
    <inertial>
      <origin xyz="0 0 0" rpy="0 0 0"/>
      <mass value="0.5"/>
      <inertia ixx="0.0004" ixy="0.0" ixz="0.0" iyy="0.0002" iyz="0.0" izz="0.0004"/>
    </inertial>
  </link>
  <joint name="wheel_fr_joint" type="continuous">
    <parent link="base_link"/>
    <child link="wheel_fr_link"/>
    <origin xyz="0.16 -0.18 0.05" rpy="0 0 0"/>
    <axis xyz="0 1 0"/>
    <dynamics damping="0.01" friction="0.0"/>
  </joint>

  <link name="wheel_rl_link">
    <visual>
      <origin xyz="0 0 0" rpy="1.5707963 0 0"/>
      <geometry><cylinder radius="0.05" length="0.03"/></geometry>
    </visual>
    <collision>
      <origin xyz="0 0 0" rpy="1.5707963 0 0"/>
      <geometry><cylinder radius="0.05" length="0.03"/></geometry>
    </collision>
    <inertial>
      <origin xyz="0 0 0" rpy="0 0 0"/>
      <mass value="0.5"/>
      <inertia ixx="0.0004" ixy="0.0" ixz="0.0" iyy="0.0002" iyz="0.0" izz="0.0004"/>
    </inertial>
  </link>
  <joint name="wheel_rl_joint" type="continuous">
    <parent link="base_link"/>
    <child link="wheel_rl_link"/>
    <origin xyz="-0.16 0.18 0.05" rpy="0 0 0"/>
    <axis xyz="0 1 0"/>
    <dynamics damping="0.01" friction="0.0"/>
  </joint>

  <link name="wheel_rr_link">
    <visual>
      <origin xyz="0 0 0" rpy="1.5707963 0 0"/>
      <geometry><cylinder radius="0.05" length="0.03"/></geometry>
    </visual>
    <collision>
      <origin xyz="0 0 0" rpy="1.5707963 0 0"/>
      <geometry><cylinder radius="0.05" length="0.03"/></geometry>
    </collision>
    <inertial>
      <origin xyz="0 0 0" rpy="0 0 0"/>
      <mass value="0.5"/>
      <inertia ixx="0.0004" ixy="0.0" ixz="0.0" iyy="0.0002" iyz="0.0" izz="0.0004"/>
    </inertial>
  </link>
  <joint name="wheel_rr_joint" type="continuous">
    <parent link="base_link"/>
    <child link="wheel_rr_link"/>
    <origin xyz="-0.16 -0.18 0.05" rpy="0 0 0"/>
    <axis xyz="0 1 0"/>
    <dynamics damping="0.01" friction="0.0"/>
  </joint>

  <link name="laser_frame">
    <visual>
      <origin xyz="0 0 0" rpy="0 0 0"/>
      <geometry>
        <cylinder radius="0.035" length="0.05"/>
      </geometry>
    </visual>
    <collision>
      <origin xyz="0 0 0" rpy="0 0 0"/>
      <geometry>
        <cylinder radius="0.035" length="0.05"/>
      </geometry>
    </collision>
    <inertial>
      <origin xyz="0 0 0" rpy="0 0 0"/>
      <mass value="0.10"/>
      <inertia ixx="1e-4" ixy="0" ixz="0" iyy="1e-4" iyz="0" izz="1e-4"/>
    </inertial>
  </link>

  <joint name="laser_joint" type="fixed">
    <parent link="base_link"/>
    <child link="laser_frame"/>
    <origin xyz="0.00 0.00 0.10" rpy="0 0 0"/>
  </joint>

  <link name="camera_link">
    <visual>
      <origin xyz="0 0 0" rpy="0 0 0"/>
      <geometry><box size="0.03 0.05 0.03"/></geometry>
    </visual>
    <inertial>
      <origin xyz="0 0 0" rpy="0 0 0"/>
      <mass value="0.05"/>
      <inertia ixx="1e-5" ixy="0" ixz="0" iyy="1e-5" iyz="0" izz="1e-5"/>
    </inertial>
  </link>

  <joint name="camera_joint" type="fixed">
    <parent link="base_link"/>
    <child link="camera_link"/>
    <origin xyz="0.21 0 0.25" rpy="0 0 0"/>
  </joint>

  <link name="camera_optical_link"/>
  <joint name="camera_optical_joint" type="fixed">
    <parent link="camera_link"/>
    <child link="camera_optical_link"/>
    <origin xyz="0 0 0" rpy="-1.5707963 0 -1.5707963"/>
  </joint>

  <!-- ros2_control is currently disabled to avoid parsing errors on Humble/WSLg -->
  <!--
  <ros2_control name="GazeboSystem" type="system">
    <hardware>
      <plugin>gazebo_ros2_control/GazeboSystem</plugin>
    </hardware>
    <joint name="wheel_fl_joint"><command_interface name="velocity"/><state_interface name="velocity"/><state_interface name="position"/></joint>
    <joint name="wheel_fr_joint"><command_interface name="velocity"/><state_interface name="velocity"/><state_interface name="position"/></joint>
    <joint name="wheel_rl_joint"><command_interface name="velocity"/><state_interface name="velocity"/><state_interface name="position"/></joint>
    <joint name="wheel_rr_joint"><command_interface name="velocity"/><state_interface name="velocity"/><state_interface name="position"/></joint>
  </ros2_control>
  -->

  <gazebo reference="base_link">
    <mu1>0.2</mu1>
    <mu2>0.2</mu2>
    <material>Gazebo/Blue</material>
  </gazebo>

  <gazebo>
    <plugin name="gazebo_ros_planar_move" filename="libgazebo_ros_planar_move.so">
      <ros>
        <namespace>/</namespace>
      </ros>
      <update_rate>30</update_rate>
      <publish_rate>20</publish_rate>
      <publish_odom>true</publish_odom>
      <publish_odom_tf>true</publish_odom_tf>
      <odometry_frame>odom</odometry_frame>
      <robot_base_frame>base_link</robot_base_frame>
      <covariance_x>0.0001</covariance_x>
      <covariance_y>0.0001</covariance_y>
      <covariance_yaw>0.01</covariance_yaw>
    </plugin>
  </gazebo>

  <!-- gazebo_ros2_control is currently disabled to avoid parsing errors on Humble/WSLg -->
  <!--
  <gazebo>
    <plugin name="gazebo_ros2_control" filename="libgazebo_ros2_control.so">
      <parameters>/home/poomjai/ros2_ws/src/mecanum4_description/config/mecanum_controllers.yaml</parameters>
    </plugin>
  </gazebo>
  -->

  <gazebo reference="wheel_fl_link"><mu1>0.0</mu1><mu2>0.0</mu2><kp>100000.0</kp><kd>1.0</kd><minDepth>0.001</minDepth><maxVel>1.0</maxVel><material>Gazebo/Black</material></gazebo>
  <gazebo reference="wheel_fr_link"><mu1>0.0</mu1><mu2>0.0</mu2><kp>100000.0</kp><kd>1.0</kd><minDepth>0.001</minDepth><maxVel>1.0</maxVel><material>Gazebo/Black</material></gazebo>
  <gazebo reference="wheel_rl_link"><mu1>0.0</mu1><mu2>0.0</mu2><kp>100000.0</kp><kd>1.0</kd><minDepth>0.001</minDepth><maxVel>1.0</maxVel><material>Gazebo/Black</material></gazebo>
  <gazebo reference="wheel_rr_link"><mu1>0.0</mu1><mu2>0.0</mu2><kp>100000.0</kp><kd>1.0</kd><minDepth>0.001</minDepth><maxVel>1.0</maxVel><material>Gazebo/Black</material></gazebo>

  <gazebo reference="camera_link">
    <sensor type="camera" name="camera_sensor">
      <update_rate>60</update_rate>
      <visualize>false</visualize>
      <camera>
        <horizontal_fov>1.047</horizontal_fov>
        <image>
          <width>640</width>
          <height>480</height>
          <format>R8G8B8</format>
        </image>
        <clip>
          <near>0.05</near>
          <far>20.0</far>
        </clip>
      </camera>
      <plugin name="camera_controller" filename="libgazebo_ros_camera.so">
        <ros>
          <remapping>~/image_raw:=/camera/image_raw</remapping>
          <remapping>~/camera_info:=/camera/camera_info</remapping>
        </ros>
        <camera_name>camera</camera_name>
        <frame_name>camera_optical_link</frame_name>
      </plugin>
    </sensor>
  </gazebo>

  <gazebo reference="laser_frame">
    <sensor type="ray" name="laser_sensor">
      <pose>0 0 0 0 0 0</pose>
      <visualize>true</visualize>
      <update_rate>10</update_rate>
      <ray>
        <scan>
          <horizontal>
            <samples>360</samples>
            <resolution>1</resolution>
            <min_angle>-3.14159</min_angle>
            <max_angle>3.14159</max_angle>
          </horizontal>
        </scan>
        <range>
          <min>0.35</min>
          <max>12.0</max>
          <resolution>0.01</resolution>
        </range>
        <noise>
          <type>gaussian</type>
          <mean>0.0</mean>
          <stddev>0.01</stddev>
        </noise>
      </ray>
      <plugin name="gazebo_ros_laser" filename="libgazebo_ros_ray_sensor.so">
        <ros>
          <remapping>~/out:=scan</remapping>
        </ros>
        <output_type>sensor_msgs/LaserScan</output_type>
        <frame_name>laser_frame</frame_name>
      </plugin>
    </sensor>
  </gazebo>

</robot>
