<?xml version="1.0"?>
<robot name="mecanum4_lidar">

    <link name="base_link">
    <inertial>
      <origin xyz="0 0 0" rpy="0 0 0"/>
      <mass value="0.001"/>
      <inertia ixx="1e-6" ixy="0" ixz="0" iyy="1e-6" iyz="0" izz="1e-6"/>
    </inertial>
  </link>

    <link name="chassis_link">
    <visual>
      <origin xyz="0 0 0.10" rpy="0 0 0"/>
      <geometry>
        <box size="0.40 0.30 0.12"/>
      </geometry>
    </visual>
    <collision>
      <origin xyz="0 0 0.10" rpy="0 0 0"/>
      <geometry>
        <box size="0.40 0.30 0.12"/>
      </geometry>
    </collision>
    <inertial>
      <origin xyz="0 0 0.10" rpy="0 0 0"/>
      <mass value="10.0"/>
      <inertia ixx="0.10" ixy="0.0" ixz="0.0" iyy="0.20" iyz="0.0" izz="0.25"/>
    </inertial>
  </link>

  <joint name="base_to_chassis" type="fixed">
    <parent link="base_link"/>
    <child link="chassis_link"/>
    <origin xyz="0 0 0" rpy="0 0 0"/>
  </joint>

  
  <link name="wheel_fl_link">
    <visual>
      <origin xyz="0 0 0" rpy="1.5707963 0 0"/>
      <geometry><cylinder radius="0.05" length="0.03"/></geometry>
    </visual>
    <collision>
      <origin xyz="0 0 0" rpy="1.5707963 0 0"/>
      <geometry><cylinder radius="0.05" length="0.03"/></geometry>
    </collision>
    <inertial>
      <origin xyz="0 0 0" rpy="0 0 0"/>
      <mass value="0.5"/>
      <inertia ixx="0.0004" ixy="0.0" ixz="0.0" iyy="0.0002" iyz="0.0" izz="0.0004"/>
    </inertial>
  </link>
  <joint name="wheel_fl_joint" type="continuous">
    <parent link="chassis_link"/>
    <child link="wheel_fl_link"/>
    <origin xyz="0.16 0.18 0.05" rpy="0 0 0"/>
    <axis xyz="0 1 0"/>
    <dynamics damping="0.2" friction="0.05"/>
  </joint>

  <link name="wheel_fr_link">
    <visual>
      <origin xyz="0 0 0" rpy="1.5707963 0 0"/>
      <geometry><cylinder radius="0.05" length="0.03"/></geometry>
    </visual>
    <collision>
      <origin xyz="0 0 0" rpy="1.5707963 0 0"/>
      <geometry><cylinder radius="0.05" length="0.03"/></geometry>
    </collision>
    <inertial>
      <origin xyz="0 0 0" rpy="0 0 0"/>
      <mass value="0.5"/>
      <inertia ixx="0.0004" ixy="0.0" ixz="0.0" iyy="0.0002" iyz="0.0" izz="0.0004"/>
    </inertial>
  </link>
  <joint name="wheel_fr_joint" type="continuous">
    <parent link="chassis_link"/>
    <child link="wheel_fr_link"/>
    <origin xyz="0.16 -0.18 0.05" rpy="0 0 0"/>
    <axis xyz="0 1 0"/>
    <dynamics damping="0.2" friction="0.05"/>
  </joint>

  <link name="wheel_rl_link">
    <visual>
      <origin xyz="0 0 0" rpy="1.5707963 0 0"/>
      <geometry><cylinder radius="0.05" length="0.03"/></geometry>
    </visual>
    <collision>
      <origin xyz="0 0 0" rpy="1.5707963 0 0"/>
      <geometry><cylinder radius="0.05" length="0.03"/></geometry>
    </collision>
    <inertial>
      <origin xyz="0 0 0" rpy="0 0 0"/>
      <mass value="0.5"/>
      <inertia ixx="0.0004" ixy="0.0" ixz="0.0" iyy="0.0002" iyz="0.0" izz="0.0004"/>
    </inertial>
  </link>
  <joint name="wheel_rl_joint" type="continuous">
    <parent link="chassis_link"/>
    <child link="wheel_rl_link"/>
    <origin xyz="-0.16 0.18 0.05" rpy="0 0 0"/>
    <axis xyz="0 1 0"/>
    <dynamics damping="0.2" friction="0.05"/>
  </joint>

  <link name="wheel_rr_link">
    <visual>
      <origin xyz="0 0 0" rpy="1.5707963 0 0"/>
      <geometry><cylinder radius="0.05" length="0.03"/></geometry>
    </visual>
    <collision>
      <origin xyz="0 0 0" rpy="1.5707963 0 0"/>
      <geometry><cylinder radius="0.05" length="0.03"/></geometry>
    </collision>
    <inertial>
      <origin xyz="0 0 0" rpy="0 0 0"/>
      <mass value="0.5"/>
      <inertia ixx="0.0004" ixy="0.0" ixz="0.0" iyy="0.0002" iyz="0.0" izz="0.0004"/>
    </inertial>
  </link>
  <joint name="wheel_rr_joint" type="continuous">
    <parent link="chassis_link"/>
    <child link="wheel_rr_link"/>
    <origin xyz="-0.16 -0.18 0.05" rpy="0 0 0"/>
    <axis xyz="0 1 0"/>
    <dynamics damping="0.2" friction="0.05"/>
  </joint>

    <link name="laser_frame">
    <visual>
      <origin xyz="0 0 0" rpy="0 0 0"/>
      <geometry>
        <cylinder radius="0.035" length="0.05"/>
      </geometry>
    </visual>
    <collision>
      <origin xyz="0 0 0" rpy="0 0 0"/>
      <geometry>
        <cylinder radius="0.035" length="0.05"/>
      </geometry>
    </collision>
    <inertial>
      <origin xyz="0 0 0" rpy="0 0 0"/>
      <mass value="0.10"/>
      <inertia ixx="1e-4" ixy="0" ixz="0" iyy="1e-4" iyz="0" izz="1e-4"/>
    </inertial>
  </link>

  <joint name="laser_joint" type="fixed">
    <parent link="base_link"/>
    <child link="laser_frame"/>
    <origin xyz="0.10 0.00 0.20" rpy="0 0 0"/>
  </joint>

    <ros2_control name="GazeboSystem" type="system">
    <hardware>
      <plugin>gazebo_ros2_control/GazeboSystem</plugin>
    </hardware>

    <joint name="wheel_fl_joint">
      <command_interface name="velocity"/>
      <state_interface name="velocity"/>
      <state_interface name="position"/>
    </joint>

    <joint name="wheel_fr_joint">
      <command_interface name="velocity"/>
      <state_interface name="velocity"/>
      <state_interface name="position"/>
    </joint>

    <joint name="wheel_rl_joint">
      <command_interface name="velocity"/>
      <state_interface name="velocity"/>
      <state_interface name="position"/>
    </joint>

    <joint name="wheel_rr_joint">
      <command_interface name="velocity"/>
      <state_interface name="velocity"/>
      <state_interface name="position"/>
    </joint>
  </ros2_control>

    <gazebo>
    <plugin name="gazebo_ros2_control" filename="libgazebo_ros2_control.so">
      <parameters>/home/minmin/ros2_ws/src/mecanum4_description/config/mecanum_controllers.yaml</parameters>
    </plugin>
  </gazebo>

    <gazebo reference="wheel_fl_link">
    <mu1>0.8</mu1>
    <mu2>0.8</mu2>
    <kp>1000000.0</kp>
    <kd>10.0</kd>
    <minDepth>0.001</minDepth>
    <maxVel>0.1</maxVel>
  </gazebo>

  <gazebo reference="wheel_fr_link">
    <mu1>0.8</mu1>
    <mu2>0.8</mu2>
    <kp>1000000.0</kp>
    <kd>10.0</kd>
    <minDepth>0.001</minDepth>
    <maxVel>0.1</maxVel>
  </gazebo>

  <gazebo reference="wheel_rl_link">
    <mu1>0.8</mu1>
    <mu2>0.8</mu2>
    <kp>1000000.0</kp>
    <kd>10.0</kd>
    <minDepth>0.001</minDepth>
    <maxVel>0.1</maxVel>
  </gazebo>

  <gazebo reference="wheel_rr_link">
    <mu1>0.8</mu1>
    <mu2>0.8</mu2>
    <kp>1000000.0</kp>
    <kd>10.0</kd>
    <minDepth>0.001</minDepth>
    <maxVel>0.1</maxVel>
  </gazebo>

    <gazebo reference="laser_frame">
    <sensor type="ray" name="laser_sensor">
      <pose>0 0 0 0 0 0</pose>
      <visualize>true</visualize>
      <update_rate>10</update_rate>
      <ray>
        <scan>
          <horizontal>
            <samples>720</samples>
            <resolution>1</resolution>
            <min_angle>-3.14159</min_angle>
            <max_angle>3.14159</max_angle>
          </horizontal>
        </scan>
        <range>
          <min>0.12</min>
          <max>12.0</max>
          <resolution>0.01</resolution>
        </range>
        <noise>
          <type>gaussian</type>
          <mean>0.0</mean>
          <stddev>0.01</stddev>
        </noise>
      </ray>
      <plugin name="gazebo_ros_laser" filename="libgazebo_ros_ray_sensor.so">
        <ros>
          <remapping>~/out:=scan</remapping>
        </ros>
        <output_type>sensor_msgs/LaserScan</output_type>
        <frame_name>laser_frame</frame_name>
      </plugin>
    </sensor>
  </gazebo>

</robot>
